Workbook

Sheet Summary
B1: Company Fundamentals - Financial Summary | I1: ** | J1: Refer to Notes for detailed analysis
B2: Company Name | C2: Cyberia Inc.
B3: Country of Headquarters | C3: Bermuda
B4: Industry Group | C4: P&C Insurance
B5: Date of Analysis | C5: 45990
B6: Name of Analyst | C6: Abhishek Kaushish
B8: Key Assumptions
B10: Parameter | C10: Value
B11: Forecast Period | C11: 2025- 2030
B12: WACC | C12: 0.114216
B13: Perpetual Growth Rate | C13: 0.02
B14: FCF in Terminal Year | C14: 5032490.7
B16: Valuation Output
B17: Particular | C17: Value
B18: PV of FCFs | C18: =DCF!C19 -> 16892295
B19: PV of Terminal Value | C19: =DCF!C17 -> 31752571
B20: Enterprise Value (EV) | C20: =SUM(C18:C19) -> 48644865
B21: Net Debt | C21: =DCF!C21 -> -3.5632017e+08
B22: Minority Interest | C22: 0
B23: Equity Value | C23: =C20-C21 -> 4.0496503e+08
B26: Conclusion: **
B27: Cyberia Inc. demonstrates robust cash generation and a significant net cash position, which materially enhances Equity Value. DCF analysis confirms that the company's intrinsic value is well supported under conservative assumptions, with upside potential if growth rates improve or cost of capital declines.

Sheet Financials
C2: 2024A | D2: 2025E | E2: 2026E | F2: 2027E | G2: 2028E | H2: 2029E | I2: 2030E
B3: Income Statement
B4: Premium Written | C4: =Assumptions!$C$2 -> 100000000 | D4: =C4+(C4*Assumptions!$C$3) -> 105000000 | E4: =D4+(D4*Assumptions!$C$3) -> 110250000 | F4: =E4+(E4*Assumptions!$C$3) -> 115762500 | G4: =F4+(F4*Assumptions!$C$3) -> 121550625 | H4: =G4+(G4*Assumptions!$C$3) -> 1.2762816e+08 | I4: =H4+(H4*Assumptions!$C$3) -> 1.3400956e+08
B6: Operating Costs
B7: Claims Paid | C7: ='Claims & Reserve Modeling'!C26 -> 28000000 | D7: ='Claims & Reserve Modeling'!D26 -> 57400000 | E7: ='Claims & Reserve Modeling'!E26 -> 74270000 | F7: ='Claims & Reserve Modeling'!F26 -> 77983500 | G7: ='Claims & Reserve Modeling'!G26 -> 81882675 | H7: ='Claims & Reserve Modeling'!H26 -> 85976809 | I7: ='Claims & Reserve Modeling'!I26 -> 90275649
B9: Underwriting Expenses | C9: =C4*Assumptions!$C$5 -> 25000000 | D9: =D4*Assumptions!$C$5 -> 26250000 | E9: =E4*Assumptions!$C$5 -> 27562500 | F9: =F4*Assumptions!$C$5 -> 28940625 | G9: =G4*Assumptions!$C$5 -> 30387656 | H9: =H4*Assumptions!$C$5 -> 31907039 | I9: =I4*Assumptions!$C$5 -> 33502391
B11: Change in Claim Reserve | C11: ='Claims & Reserve Modeling'!C28 -> 42000000 | D11: ='Claims & Reserve Modeling'!D28 -> 16100000 | E11: ='Claims & Reserve Modeling'!E28 -> 2905000 | F11: ='Claims & Reserve Modeling'!F28 -> 3050250 | G11: ='Claims & Reserve Modeling'!G28 -> 3202762.5 | H11: ='Claims & Reserve Modeling'!H28 -> 3362900.6 | I11: ='Claims & Reserve Modeling'!I28 -> 3531045.7
B13: Underwriting Profit | C13: =C4-C7-C9-C11 -> 5000000 | D13: =D4-D7-D9-D11 -> 5250000 | E13: =E4-E7-E9-E11 -> 5512500 | F13: =F4-F7-F9-F11 -> 5788125 | G13: =G4-G7-G9-G11 -> 6077531.2 | H13: =H4-H7-H9-H11 -> 6381407.8 | I13: =I4-I7-I9-I11 -> 6700478.2
B15: Investment Income | C15: ='Claims & Reserve Modeling'!C$29*Assumptions!$C$6 -> 840000 | D15: ='Claims & Reserve Modeling'!D$29*Assumptions!$C$6 -> 2002000 | E15: ='Claims & Reserve Modeling'!E$29*Assumptions!$C$6 -> 2382100 | F15: ='Claims & Reserve Modeling'!F$29*Assumptions!$C$6 -> 2501205 | G15: ='Claims & Reserve Modeling'!G$29*Assumptions!$C$6 -> 2626265.2 | H15: ='Claims & Reserve Modeling'!H$29*Assumptions!$C$6 -> 2757578.5 | I15: ='Claims & Reserve Modeling'!I$29*Assumptions!$C$6 -> 2895457.4
B17: Operating Profit (EBIT) | C17: =C13+C15 -> 5840000 | D17: =D13+D15 -> 7252000 | E17: =E13+E15 -> 7894600 | F17: =F13+F15 -> 8289330 | G17: =G13+G15 -> 8703796.5 | H17: =H13+H15 -> 9138986.3 | I17: =I13+I15 -> 9595935.6
B19: Interest Expense | C19: ='Debt Schedule'!C3*6% -> 900000 | D19: ='Debt Schedule'!D3*6% -> 900000 | E19: ='Debt Schedule'!E3*6% -> 795000 | F19: ='Debt Schedule'!F3*6% -> 684750 | G19: ='Debt Schedule'!G3*6% -> 568987.5 | H19: ='Debt Schedule'!H3*6% -> 447436.88 | I19: ='Debt Schedule'!I3*6% -> 319808.72
B21: Profit before Tax | C21: =C17-C19 -> 4940000 | D21: =D17-D19 -> 6352000 | E21: =E17-E19 -> 7099600 | F21: =F17-F19 -> 7604580 | G21: =G17-G19 -> 8134809 | H21: =H17-H19 -> 8691549.4 | I21: =I17-I19 -> 9276126.9
B23: Tax Expense | C23: =C21*Assumptions!$C$27 -> 1235000 | D23: =D21*Assumptions!$C$27 -> 1588000 | E23: =E21*Assumptions!$C$27 -> 1774900 | F23: =F21*Assumptions!$C$27 -> 1901145 | G23: =G21*Assumptions!$C$27 -> 2033702.2 | H23: =H21*Assumptions!$C$27 -> 2172887.4 | I23: =I21*Assumptions!$C$27 -> 2319031.7
B25: Net Income | C25: =C21-C23 -> 3705000 | D25: =D21-D23 -> 4764000 | E25: =E21-E23 -> 5324700 | F25: =F21-F23 -> 5703435 | G25: =G21-G23 -> 6101106.8 | H25: =H21-H23 -> 6518662.1 | I25: =I21-I23 -> 6957095.2
B28: Balance Sheet as of
B29: Assets
B30: Cash & Cash Investments | C30: =Assumptions!$C$12+C4-C7+C15 -> 97840000 | D30: =C30+D4-D7+D15 -> 147442000 | E30: =D30+E4-E7+E15 -> 185804100 | F30: =E30+F4-F7+F15 -> 226084305 | G30: =F30+G4-G7+G15 -> 2.6837852e+08 | H30: =G30+H4-H7+H15 -> 3.1278745e+08 | I30: =H30+I4-I7+I15 -> 3.5941682e+08
B31: Reserves | C31: ='Claims & Reserve Modeling'!C27 -> 42000000 | D31: ='Claims & Reserve Modeling'!D27 -> 58100000 | E31: ='Claims & Reserve Modeling'!E27 -> 61005000 | F31: ='Claims & Reserve Modeling'!F27 -> 64055250 | G31: ='Claims & Reserve Modeling'!G27 -> 67258012 | H31: ='Claims & Reserve Modeling'!H27 -> 70620913 | I31: ='Claims & Reserve Modeling'!I27 -> 74151959
B32: Other Assets | C32: =C61 -> 1500000 | D32: =D61 -> 1575000 | E32: =E61 -> 1653750 | F32: =F61 -> 1736437.5 | G32: =G61 -> 1823259.4 | H32: =H61 -> 1914422.3 | I32: =I61 -> 2010143.5
B33: Total Assets | C33: =SUM(C30:C32) -> 141340000 | D33: =SUM(D30:D32) -> 207117000 | E33: =SUM(E30:E32) -> 248462850 | F33: =SUM(F30:F32) -> 2.9187599e+08 | G33: =SUM(G30:G32) -> 3.3745979e+08 | H33: =SUM(H30:H32) -> 3.8532278e+08 | I33: =SUM(I30:I32) -> 4.3557892e+08
B35: Liabilities
B36: Claims Reserve | C36: ='Claims & Reserve Modeling'!C27 -> 42000000 | D36: ='Claims & Reserve Modeling'!D27 -> 58100000 | E36: ='Claims & Reserve Modeling'!E27 -> 61005000 | F36: ='Claims & Reserve Modeling'!F27 -> 64055250 | G36: ='Claims & Reserve Modeling'!G27 -> 67258012 | H36: ='Claims & Reserve Modeling'!H27 -> 70620913 | I36: ='Claims & Reserve Modeling'!I27 -> 74151959
B37: Debt | C37: ='Debt Schedule'!C6 -> 15000000 | D37: ='Debt Schedule'!D6 -> 13250000 | E37: ='Debt Schedule'!E6 -> 11412500 | F37: ='Debt Schedule'!F6 -> 9483125 | G37: ='Debt Schedule'!G6 -> 7457281.2 | H37: ='Debt Schedule'!H6 -> 5330145.3 | I37: ='Debt Schedule'!I6 -> 3096652.6
B38: Other Liabilities
B39: Total Liabilities | C39: =SUM(C36:C38) -> 57000000 | D39: =SUM(D36:D38) -> 71350000 | E39: =SUM(E36:E38) -> 72417500 | F39: =SUM(F36:F38) -> 73538375 | G39: =SUM(G36:G38) -> 74715294 | H39: =SUM(H36:H38) -> 75951058 | I39: =SUM(I36:I38) -> 77248611
B41: Equity
B42: Retained Earnings | C42: =C33-C39 -> 84340000 | D42: =D33-D39 -> 135767000 | E42: =E33-E39 -> 176045350 | F42: =F33-F39 -> 2.1833762e+08 | G42: =G33-G39 -> 2.627445e+08 | H42: =H33-H39 -> 3.0937172e+08 | I42: =I33-I39 -> 3.5833031e+08
B44: Balance Sheet Check | C44: =C33=(C39+C42) -> TRUE | D44: =D33=(D39+D42) -> TRUE | E44: =E33=(E39+E42) -> TRUE | F44: =F33=(F39+F42) -> TRUE | G44: =G33=(G39+G42) -> TRUE | H44: =H33=(H39+H42) -> TRUE | I44: =I33=(I39+I42) -> TRUE
B45: Equity | C45: =C42/C33 -> 0.59671714 | D45: =D42/D33 -> 0.65550872 | E45: =E42/E33 -> 0.70853792 | F45: =F42/F33 -> 0.74804925 | G45: =G42/G33 -> 0.77859497 | H45: =H42/H33 -> 0.80288978 | I45: =I42/I33 -> 0.82265301
B46: Debt | C46: =C37/C33 -> 0.10612707 | D46: =D39/D33 -> 0.34449128 | E46: =E39/E33 -> 0.29146208 | F46: =F39/F33 -> 0.25195075 | G46: =G39/G33 -> 0.22140503 | H46: =H39/H33 -> 0.19711022 | I46: =I39/I33 -> 0.17734699
B47: Claims Reserve | C47: =C36/C33 -> 0.29715579 | D47: =D36/D33 -> 0.28051777 | E47: =E36/E33 -> 0.24552966 | F47: =F36/F33 -> 0.2194605 | G47: =G36/G33 -> 0.19930674 | H47: =H36/H33 -> 0.18327728 | I47: =I36/I33 -> 0.17023771
B50: Statement of Cash Flow
B51: Operating Cash Flow
B52: Premium Written | C52: =C4 -> 100000000 | D52: =D4 -> 105000000 | E52: =E4 -> 110250000 | F52: =F4 -> 115762500 | G52: =G4 -> 121550625 | H52: =H4 -> 1.2762816e+08 | I52: =I4 -> 1.3400956e+08
B53: Claims Paid | C53: ='Claims & Reserve Modeling'!C26 -> 28000000 | D53: ='Claims & Reserve Modeling'!D26 -> 57400000 | E53: ='Claims & Reserve Modeling'!E26 -> 74270000 | F53: ='Claims & Reserve Modeling'!F26 -> 77983500 | G53: ='Claims & Reserve Modeling'!G26 -> 81882675 | H53: ='Claims & Reserve Modeling'!H26 -> 85976809 | I53: ='Claims & Reserve Modeling'!I26 -> 90275649
B54: Expenses | C54: =C9 -> 25000000 | D54: =D9 -> 26250000 | E54: =E9 -> 27562500 | F54: =F9 -> 28940625 | G54: =G9 -> 30387656 | H54: =H9 -> 31907039 | I54: =I9 -> 33502391
B55: Investment Income | C55: =C15 -> 840000 | D55: =D15 -> 2002000 | E55: =E15 -> 2382100 | F55: =F15 -> 2501205 | G55: =G15 -> 2626265.2 | H55: =H15 -> 2757578.5 | I55: =I15 -> 2895457.4
B56: Change in Reserve | C56: ='Claims & Reserve Modeling'!C28 -> 42000000 | D56: ='Claims & Reserve Modeling'!D28 -> 16100000 | E56: ='Claims & Reserve Modeling'!E28 -> 2905000 | F56: ='Claims & Reserve Modeling'!F28 -> 3050250 | G56: ='Claims & Reserve Modeling'!G28 -> 3202762.5 | H56: ='Claims & Reserve Modeling'!H28 -> 3362900.6 | I56: ='Claims & Reserve Modeling'!I28 -> 3531045.7
B58: Cash Flow from Operating Activites | C58: =C52-C53-C54+C55-C56 -> 5840000 | D58: =D52-D53-D54+D55-D56 -> 7252000 | E58: =E52-E53-E54+E55-E56 -> 7894600 | F58: =F52-F53-F54+F55-F56 -> 8289330 | G58: =G52-G53-G54+G55-G56 -> 8703796.5 | H58: =H52-H53-H54+H55-H56 -> 9138986.3 | I58: =I52-I53-I54+I55-I56 -> 9595935.6
B60: Investing Cash Flow
...

Sheet DCF
B1: Cyberia Inc.
B2: Discounted Cash Flow
D3: 1 | E3: 2 | F3: 3 | G3: 4 | H3: 5 | I3: 5
C4: 2024A | D4: 2025E | E4: 2026E | F4: 2027E | G4: 2028E | H4: 2029E | I4: 2030E
B6: Free Cash Flow | C6: =Financials!C58-Financials!C61-Financials!C69+Financials!C68 -> 3440000 | D6: =Financials!D58-Financials!D61-Financials!D69+Financials!D68 -> 3027000 | E6: =Financials!E58-Financials!E61-Financials!E69+Financials!E68 -> 3608350 | F6: =Financials!F58-Financials!F61-Financials!F69+Financials!F68 -> 3938767.5 | G6: =Financials!G58-Financials!G61-Financials!G69+Financials!G68 -> 4285705.9 | H6: =Financials!H58-Financials!H61-Financials!H69+Financials!H68 -> 4649991.2 | I6: =Financials!I58-Financials!I61-Financials!I69+Financials!I68 -> 5032490.7
B8: Factor | D8: =1/(1+$C$14)^D3 -> 0.89753716 | E8: =1/(1+$C$14)^E3 -> 0.80557295 | F8: =1/(1+$C$14)^F3 -> 0.72303166 | G8: =1/(1+$C$14)^G3 -> 0.64894778 | H8: =1/(1+$C$14)^H3 -> 0.58245474 | I8: =1/(1+$C$14)^I3 -> 0.58245474
B10: Discounted FCF | D10: =D6*D8 -> 2716845 | E10: =E6*E8 -> 2906789.2 | F10: =F6*F8 -> 2847853.6 | G10: =G6*G8 -> 2781199.3 | H10: =H6*H8 -> 2708409.4 | I10: =I6*I8 -> 2931198.1
B12: FCF in 2030 | C12: =I6 -> 5032490.7
B13: PGR | C13: =Assumptions!C8 -> 0.02
B14: WACC | C14: =Assumptions!C17 -> 0.11416
B16: Terminal Value | C16: =(C12*(1+C13))/(C14-C13) -> 54515086
B17: Discounted Terminal Value | C17: =C16*I8 -> 31752571
B19: PV of CF | C19: =SUM(D10:I10) -> 16892295
B20: EV | C20: =C17+C19 -> 48644865
B21: Net Debt | C21: =Financials!I37-Financials!I30 -> -3.5632017e+08
B22: Minority Interest | C22: 0
B23: Equity Value | C23: =C20-C21 -> 4.0496503e+08
B25: Senstivity Analysis
D26: WACC
B27: PGR | C27: =C20 -> 48644865 | D27: 0.105 | E27: 0.11 | F27: 0.115 | G27: 0.12 | H27: 0.125
C28: 0.01 | D28: 49842161 | E28: 47268884 | F28: 44939143 | G28: 42819842 | H28: 40883636
C29: 0.015 | D29: 51816118 | E29: 49013651 | F29: 46489616 | G29: 44204361 | H29: 42125438
C30: 0.02 | D30: 54022306 | E30: 50952281 | F30: 48203296 | G30: 45727332 | H30: 43485507
C31: 0.025 | D31: 56504267 | E31: 53118985 | F31: 50107386 | G31: 47410615 | H31: 44981583
C32: 0.03 | D32: 59317156 | E32: 55556527 | F32: 52235486 | G32: 49280931 | H32: 46635140

Sheet Debt Schedule
M1: Debt Strategy: Controlled Growth + Repayment
C2: =DCF!C4 -> 2024A | D2: =DCF!D4 -> 2025E | E2: =DCF!E4 -> 2026E | F2: =DCF!F4 -> 2027E | G2: =DCF!G4 -> 2028E | H2: =DCF!H4 -> 2029E | I2: =DCF!I4 -> 2030E
B3: Opening Debt | C3: =Assumptions!C13 -> 15000000 | D3: =C6 -> 15000000 | E3: =D6 -> 13250000 | F3: =E6 -> 11412500 | G3: =F6 -> 9483125 | H3: =G6 -> 7457281.2 | I3: =H6 -> 5330145.3 | M3: Assumptions
B4: Growth | C4: 0 | D4: =C3*5% -> 750000 | E4: =D6*5% -> 662500 | F4: =E6*5% -> 570625 | G4: =F6*5% -> 474156.25 | H4: =G6*5% -> 372864.06 | I4: =H6*5% -> 266507.27 | M4: Started with 15M in 2024
B5: Repayment | C5: 0 | D5: 2500000 | E5: 2500000 | F5: 2500000 | G5: 2500000 | H5: 2500000 | I5: 2500000 | M5: Grow debt by 5% annually; reflecting expansion
B6: Closing Debt | C6: =+C3+C4-C5 -> 15000000 | D6: =+D3+D4-D5 -> 13250000 | E6: =+E3+E4-E5 -> 11412500 | F6: =+F3+F4-F5 -> 9483125 | G6: =+G3+G4-G5 -> 7457281.2 | H6: =+H3+H4-H5 -> 5330145.3 | I6: =+I3+I4-I5 -> 3096652.6 | M6: Repay 2.5M per year; reflecting disciplined deleveraging

Sheet Claims & Reserve Modeling
B2: Claims Modeling
B3: Year | C3: =DCF!C4 -> 2024A | D3: =DCF!D4 -> 2025E | E3: =DCF!E4 -> 2026E | F3: =DCF!F4 -> 2027E | G3: =DCF!G4 -> 2028E | H3: =DCF!H4 -> 2029E | I3: 2023E | N3: Claims Payout Ratio
B4: Premium | C4: =Financials!C4 -> 100000000 | D4: =Financials!D4 -> 105000000 | E4: =Financials!E4 -> 110250000 | F4: =Financials!F4 -> 115762500 | G4: =Financials!G4 -> 121550625 | H4: =Financials!H4 -> 1.2762816e+08 | I4: =Financials!I4 -> 1.3400956e+08 | N4: Normal
B5: Total Claims | C5: =C4*Assumptions!$C$4 -> 70000000 | D5: =D4*Assumptions!$C$4 -> 73500000 | E5: =E4*Assumptions!$C$4 -> 77175000 | F5: =F4*Assumptions!$C$4 -> 81033750 | G5: =G4*Assumptions!$C$4 -> 85085438 | H5: =H4*Assumptions!$C$4 -> 89339709 | I5: =I4*Assumptions!$C$4 -> 93806695 | N5: Year 1 | O5: 0.4
B6: Paid Year 1 | C6: =C5*$O$5 -> 28000000 | D6: =D5*$O$5 -> 29400000 | E6: =E5*$O$5 -> 30870000 | F6: =F5*$O$5 -> 32413500 | G6: =G5*$O$5 -> 34034175 | H6: =H5*$O$5 -> 35735884 | I6: =I5*$O$5 -> 37522678 | N6: Year 2 | O6: 0.4
B7: Paid Year 2 | C7: =C5*$O$6 -> 28000000 | D7: =D5*$O$6 -> 29400000 | E7: =E5*$O$6 -> 30870000 | F7: =F5*$O$6 -> 32413500 | G7: =G5*$O$6 -> 34034175 | H7: =H5*$O$6 -> 35735884 | I7: =I5*$O$6 -> 37522678 | N7: Year 3 | O7: 0.2
B8: Paid Year 3 | C8: =C5*$O$7 -> 14000000 | D8: =D5*$O$7 -> 14700000 | E8: =E5*$O$7 -> 15435000 | F8: =F5*$O$7 -> 16206750 | G8: =G5*$O$7 -> 17017088 | H8: =H5*$O$7 -> 17867942 | I8: =I5*$O$7 -> 18761339
B11: Actual Pay Perod/ Claims Period | C11: 2024 Claims | D11: 2025 Claims | E11: 2026 Claims | F11: 2027 Claims | G11: 2028 Claims | H11: 2029 Claims | I11: 20230 Claims | J11: Total Paid
B12: 2024 | C12: =C6 -> 28000000 | D12: 0 | E12: 0 | F12: 0 | G12: 0 | H12: 0 | I12: 0 | J12: =SUM(C12:I12) -> 28000000
B13: 2025 | C13: =C7 -> 28000000 | D13: =D6 -> 29400000 | E13: 0 | F13: 0 | G13: 0 | H13: 0 | I13: 0 | J13: =SUM(C13:I13) -> 57400000
B14: 2026 | C14: =C8 -> 14000000 | D14: =D7 -> 29400000 | E14: =E6 -> 30870000 | F14: 0 | G14: 0 | H14: 0 | I14: 0 | J14: =SUM(C14:I14) -> 74270000
B15: 2027 | C15: 0 | D15: =D8 -> 14700000 | E15: =E7 -> 30870000 | F15: =F6 -> 32413500 | G15: 0 | H15: 0 | I15: 0 | J15: =SUM(C15:I15) -> 77983500
B16: 2028 | C16: 0 | D16: 0 | E16: =E8 -> 15435000 | F16: =F7 -> 32413500 | G16: =G6 -> 34034175 | H16: 0 | I16: 0 | J16: =SUM(C16:I16) -> 81882675
B17: 2029 | C17: 0 | D17: 0 | E17: 0 | F17: =F8 -> 16206750 | G17: =G7 -> 34034175 | H17: =H6 -> 35735884 | I17: 0 | J17: =SUM(C17:I17) -> 85976809
B18: 2030 | C18: 0 | D18: 0 | E18: 0 | F18: 0 | G18: =G8 -> 17017088 | H18: =H7 -> 35735884 | I18: =I6 -> 37522678 | J18: =SUM(C18:I18) -> 90275649
C19: =SUM(C12:C18) -> 70000000 | D19: =SUM(D12:D18) -> 73500000 | E19: =SUM(E12:E18) -> 77175000 | F19: =SUM(F12:F18) -> 81033750 | G19: =SUM(G12:G18) -> 85085438 | H19: =SUM(H12:H18) -> 71471768 | I19: =SUM(I12:I18) -> 37522678
B20: Check | C20: =C5=C19 -> TRUE | D20: =D5=D19 -> TRUE | E20: =E5=E19 -> TRUE | F20: =F5=F19 -> TRUE | G20: =G5=G19 -> TRUE | H20: =H5=H19 -> FALSE | I20: =I5=I19 -> FALSE | J20: =SUM(J12:J17)=SUM(C5:H5) -> FALSE
B22: Reserve Modeling
B23: Year | C23: =C3 -> 2024A | D23: =D3 -> 2025E | E23: =E3 -> 2026E | F23: =F3 -> 2027E | G23: =G3 -> 2028E | H23: =H3 -> 2029E | I23: =I3 -> 2023E
B24: Opening Reserve | C24: 0 | D24: =C27 -> 42000000 | E24: =D27 -> 58100000 | F24: =E27 -> 61005000 | G24: =F27 -> 64055250 | H24: =G27 -> 67258012 | I24: =H27 -> 70620913
B25: (+)New Claims | C25: =C5 -> 70000000 | D25: =D5 -> 73500000 | E25: =E5 -> 77175000 | F25: =F5 -> 81033750 | G25: =G5 -> 85085438 | H25: =H5 -> 89339709 | I25: =I5 -> 93806695
B26: (-) Claims Paid | C26: =C12 -> 28000000 | D26: =J13 -> 57400000 | E26: =J14 -> 74270000 | F26: =J15 -> 77983500 | G26: =J16 -> 81882675 | H26: =J17 -> 85976809 | I26: =J18 -> 90275649
B27: Closing Reserve | C27: =C24+C25-C26 -> 42000000 | D27: =D24+D25-D26 -> 58100000 | E27: =E24+E25-E26 -> 61005000 | F27: =F24+F25-F26 -> 64055250 | G27: =G24+G25-G26 -> 67258012 | H27: =H24+H25-H26 -> 70620913 | I27: =I24+I25-I26 -> 74151959
B28: Change in Reserve | C28: =C27-C24 -> 42000000 | D28: =D27-D24 -> 16100000 | E28: =E27-E24 -> 2905000 | F28: =F27-F24 -> 3050250 | G28: =G27-G24 -> 3202762.5 | H28: =H27-H24 -> 3362900.6 | I28: =I27-I24 -> 3531045.7
B29: Average Reserve Balance | C29: =(C24+C27)/2 -> 21000000 | D29: =(D24+D27)/2 -> 50050000 | E29: =(E24+E27)/2 -> 59552500 | F29: =(F24+F27)/2 -> 62530125 | G29: =(G24+G27)/2 -> 65656631 | H29: =(H24+H27)/2 -> 68939463 | I29: =(I24+I27)/2 -> 72386436

Sheet Assumptions
B2: Base Premiums Written | C2: 100000000
B3: Premium Growth Rate | C3: 0.05
B4: Loss Ratio | C4: 0.7
B5: Expense Ratio | C5: 0.25
B6: Investment Yield | C6: 0.04
B7: Discount Rate | C7: 0.1
B8: Terminal Growth Rate | C8: 0.02
B9: Reserve | C9: 10000000
B10: Capex as % of Premium | C10: 0.015
B12: Opening Cash | C12: 25000000
B13: Opening Debt | C13: 15000000
B14: Net Opening Debt | C14: =C13-C12 -> -10000000
B16: WACC | C16: =(C18*C23)+(C25*C28) -> 0.09916
B17: Final WACC | C17: =C16+C32 -> 0.11416
B18: Equity | C18: 0.8
B19: Risk-Free Rate | C19: 0.0427
B20: Beta | C20: 1
B21: Equity Risk Premium | C21: 0.055
B22: Insurer Risk Premium | C22: 0.015
B23: Cost of Equity | C23: =C19+(C20*C21)+C22 -> 0.1127
B25: Debt | C25: 0.2
B26: Pre-tax Debt Cost | C26: 0.06
B27: Tax Rate | C27: 0.25
B28: Cost of Debt | C28: =C26*(1-C27) -> 0.045
B29: Adjustment
B30: Underwriting Cycle Risk | C30: 0.005
B31: Reserve Risk | C31: 0.01
C32: =C30+C31 -> 0.015

Sheet Notes
B2: Claims Modeling
B3: Claims are projected as a % of premiums written, reflecting expected payout ratios
B4: Claims Paid flow directly into Operating Cash Flow as outflows.
B5: Reserve changes are modeled separately to capture timing differences between incurred vs. paid claims.
B6: Loss ratio (Claims ÷ Premiums) is tracked to benchmark against industry norms
B8: Cash Calculations
B9: Cash balance is built dynamically from Premiums – Claims – Expenses + Investment Income – Reserve Changes – Capex – Financing Flows
B10: Premiums drive inflows, claims and expenses drive outflows
B11: Investment income is modeled as a fixed yield (e.g., 4%) on reserves
B12: By 2030, cash grows to ₹359M, reflecting strong float accumulation and retained earnings
B14: Reserve Treatment
B15: Reserves are modeled as both a liability (future claims obligation) and an asset (investable float).
... B38: Sensitivity analysis included for WACC and growth rate
